I'm sorry, but an uncaught exception occurred.

While running game code:
  File "game/script.rpy", line 547, in script
    a330 "..."
Exception: Sayer 'a330' is not defined.

-- Full Traceback ------------------------------------------------------------

Full traceback:
  File "game/script.rpy", line 547, in script
    a330 "..."
  File "/home/lastation4/Documents/renpy-7.3.5-sdk/renpy/ast.py", line 678, in execute
    who = eval_who(self.who, self.who_fast)
  File "/home/lastation4/Documents/renpy-7.3.5-sdk/renpy/ast.py", line 576, in eval_who
    raise Exception("Sayer '%s' is not defined." % who.encode("utf-8"))
Exception: Sayer 'a330' is not defined.

Linux-5.4.0-58-generic-x86_64-with-debian-bullseye-sid
Ren'Py 7.3.5.606
Love Takes Flight prealpha0.2
Sat Dec 12 15:30:23 2020
